<?xml version="1.0" ?>
<!-- =================================================================================== -->
<!-- |    This document was autogenerated by xacro from src/swc_nav_bringup/urdf/gkchair01_base.urdf | -->
<!-- |    EDITING THIS FILE BY HAND IS NOT RECOMMENDED                                 | -->
<!-- =================================================================================== -->
<robot name="gk01">
  <!-- <xacro:property name="wheel_joint_type" value="continuous" /> -->
  <!-- *********************** DRIVE WHEELS ******************************  -->
  <!-- Init colour -->
  <material name="black">
    <color rgba="0.0 0.0 0.0 1.0"/>
  </material>
  <material name="dark">
    <color rgba="0.3 0.3 0.3 1.0"/>
  </material>
  <material name="light_black">
    <color rgba="0.7 0.7 0.7 1.0"/>
  </material>
  <material name="blue">
    <color rgba="0.0 0.0 0.8 1.0"/>
  </material>
  <material name="light_blue">
    <color rgba="0.0 0.0 1.0 0.5"/>
  </material>
  <material name="green">
    <color rgba="0.0 0.8 0.0 1.0"/>
  </material>
  <material name="grey">
    <color rgba="0.5 0.5 0.5 1.0"/>
  </material>
  <material name="orange">
    <color rgba="1.0 0.4235 0.0392 1.0"/>
  </material>
  <material name="brown">
    <color rgba="0.8706 0.8118 0.7647 1.0"/>
  </material>
  <material name="red">
    <color rgba="0.8 0.0 0.0 1.0"/>
  </material>
  <material name="white">
    <color rgba="1.0 1.0 1.0 1.0"/>
  </material>
  <!-- ************************************************************************************************************************** -->
  <!-- ************************************************************************************************************************** -->
  <!-- ************************************************************************************************************************** -->
  <!-- ************************************************************************************************************************** -->
  <link name="base_footprint"/>
  <joint name="base_joint" type="fixed">
    <parent link="base_footprint"/>
    <child link="base_link"/>
    <origin rpy="0 0 0" xyz="0 0 0.29500000000000004"/>
  </joint>
  <!-- base link -->
  <link name="base_link">
    <visual>
      <origin rpy="0 0 0" xyz="0  0 0.2"/>
      <geometry>
        <!-- <mesh filename="package://swc_nav_bringup/meshes/robot_base.STL" scale="1.0 1.0 1.0"/> -->
        <box size="0.8 0.5   0.7"/>
      </geometry>
      <material name="light_blue"/>
    </visual>
    <collision>
      <origin rpy="0 0 0" xyz="0 0 0"/>
      <geometry>
        <box size="0.8 0.5 0.3"/>
      </geometry>
    </collision>
    <inertial>
      <origin rpy="1.5707963267948966 0 1.5707963267948966" xyz="0 0 0"/>
      <mass value="20.0"/>
      <inertia ixx="1.8833333333333335" ixy="0.0" ixz="0.0" iyy="1.4833333333333336" iyz="0.0" izz="1.2333333333333334"/>
    </inertial>
  </link>
  <link name="left_wheel_link">
    <visual>
      <origin rpy="0 0 1.5707963267948966" xyz="0 0 0"/>
      <geometry>
        <mesh filename="package://swc_nav_bringup/meshes/wheel2.STL" scale="0.6181818181818182 0.6181818181818182 0.6181818181818182"/>
      </geometry>
      <material name="light_black"/>
    </visual>
    <collision>
      <origin rpy="1.5707963267948966 0 0" xyz="0 0 0"/>
      <geometry>
        <cylinder length="0.07" radius="0.17"/>
      </geometry>
    </collision>
    <inertial>
      <origin rpy="1.5707963267948966 0 0" xyz="0 0 0"/>
      <mass value="5.5"/>
      <inertia ixx="0.04198333333333334" ixy="-4.2369783e-11" ixz="0" iyy="0.04198333333333334" iyz="0" izz="0.07947500000000002"/>
    </inertial>
  </link>
  <joint name="left_wheel_joint" type="continuous">
    <parent link="base_link"/>
    <child link="left_wheel_link"/>
    <origin rpy="0 0 0" xyz="-0.4 0.295 -0.125"/>
    <axis xyz="0 1 0"/>
    <!-- <limit upper="3.1415" lower="-3.1415" effort="30" velocity="5.0"/> -->
  </joint>
  <gazebo reference="left_wheel_link">
    <material>Gazebo/Black</material>
    <mu1>2.0</mu1>
    <!-- 摩擦系数 -->
    <mu2>2.0</mu2>
  </gazebo>
  <link name="right_wheel_link">
    <visual>
      <origin rpy="0 0 -1.5707963267948966" xyz="0 0 0"/>
      <geometry>
        <mesh filename="package://swc_nav_bringup/meshes/wheel2.STL" scale="0.6181818181818182 0.6181818181818182 0.6181818181818182"/>
      </geometry>
      <material name="light_black"/>
    </visual>
    <collision>
      <origin rpy="1.5707963267948966 0 0" xyz="0 0 0"/>
      <geometry>
        <cylinder length="0.07" radius="0.17"/>
      </geometry>
    </collision>
    <inertial>
      <origin rpy="1.5707963267948966 0 0" xyz="0 0 0"/>
      <mass value="5.5"/>
      <inertia ixx="0.04198333333333334" ixy="-4.2369783e-11" ixz="0" iyy="0.04198333333333334" iyz="0" izz="0.07947500000000002"/>
    </inertial>
  </link>
  <joint name="right_wheel_joint" type="continuous">
    <parent link="base_link"/>
    <child link="right_wheel_link"/>
    <origin rpy="0 0 0" xyz="-0.4 -0.295 -0.125"/>
    <axis xyz="0 1 0"/>
    <!-- <limit upper="3.1415" lower="-3.1415" effort="30" velocity="5.0"/> -->
  </joint>
  <gazebo reference="right_wheel_link">
    <material>Gazebo/Black</material>
    <mu1>2.0</mu1>
    <!-- 摩擦系数 -->
    <mu2>2.0</mu2>
  </gazebo>
  <link name="left_small_wheel_link">
    <visual>
      <origin rpy="0 0 1.5707963267948966" xyz="0 0 0"/>
      <geometry>
        <mesh filename="package://swc_nav_bringup/meshes/small_wheel.STL" scale="0.9973753280839895 0.9973753280839895 0.9973753280839895"/>
      </geometry>
      <material name="light_black"/>
    </visual>
    <collision>
      <origin rpy="1.5707963267948966 0 0" xyz="0 0 0"/>
      <geometry>
        <cylinder length="0.04" radius="0.095"/>
      </geometry>
    </collision>
    <inertial>
      <origin rpy="1.5707963267948966 0 0" xyz="0 0 0"/>
      <mass value="1.5"/>
      <inertia ixx="0.0035843750000000003" ixy="-4.2369783e-11" ixz="0" iyy="0.0035843750000000003" iyz="0" izz="0.0067687500000000005"/>
    </inertial>
  </link>
  <joint name="left_small_wheel_joint" type="fixed">
    <parent link="base_link"/>
    <child link="left_small_wheel_link"/>
    <origin rpy="0 0 0" xyz="0.29999999999999993 0.248 -0.20000000000000004"/>
    <axis xyz="0 1 0"/>
    <limit effort="30" lower="-3.1415" upper="3.1415" velocity="5.0"/>
  </joint>
  <gazebo reference="left_small_wheel_link">
    <material>Gazebo/Black</material>
    <mu1>0.001</mu1>
    <!-- 摩擦系数 -->
    <mu2>0.001</mu2>
  </gazebo>
  <link name="right_small_wheel_link">
    <visual>
      <origin rpy="0 0 -1.5707963267948966" xyz="0 0 0"/>
      <geometry>
        <mesh filename="package://swc_nav_bringup/meshes/small_wheel.STL" scale="0.9973753280839895 0.9973753280839895 0.9973753280839895"/>
      </geometry>
      <material name="light_black"/>
    </visual>
    <collision>
      <origin rpy="1.5707963267948966 0 0" xyz="0 0 0"/>
      <geometry>
        <cylinder length="0.04" radius="0.095"/>
      </geometry>
    </collision>
    <inertial>
      <origin rpy="1.5707963267948966 0 0" xyz="0 0 0"/>
      <mass value="1.5"/>
      <inertia ixx="0.0035843750000000003" ixy="-4.2369783e-11" ixz="0" iyy="0.0035843750000000003" iyz="0" izz="0.0067687500000000005"/>
    </inertial>
  </link>
  <joint name="right_small_wheel_joint" type="fixed">
    <parent link="base_link"/>
    <child link="right_small_wheel_link"/>
    <origin rpy="0 0 0" xyz="0.29999999999999993 -0.248 -0.20000000000000004"/>
    <axis xyz="0 1 0"/>
    <limit effort="30" lower="-3.1415" upper="3.1415" velocity="5.0"/>
  </joint>
  <gazebo reference="right_small_wheel_link">
    <material>Gazebo/Black</material>
    <mu1>0.001</mu1>
    <!-- 摩擦系数 -->
    <mu2>0.001</mu2>
  </gazebo>
  <!-- laser joint -->
  <joint name="laser_joint" type="fixed">
    <parent link="base_link"/>
    <child link="laser_link"/>
    <origin xyz="0.44 -0.25 -0.08500000000000003"/>
  </joint>
  <!-- laser link -->
  <link name="laser_link">
    <visual>
      <origin rpy="0 0 0" xyz="0 0 0"/>
      <geometry>
        <cylinder length="0.02" radius="0.02"/>
      </geometry>
      <material name="black"/>
    </visual>
    <inertial>
      <origin rpy="1.5707963267948966 0 0" xyz="0 0 0"/>
      <mass value="0.02"/>
      <inertia ixx="2.6666666666666664e-06" ixy="-4.2369783e-11" ixz="0" iyy="2.6666666666666664e-06" iyz="0" izz="4.000000000000001e-06"/>
    </inertial>
  </link>
  <!-- imu joint -->
  <joint name="imu_joint" type="fixed">
    <parent link="laser_link"/>
    <child link="imu_link"/>
    <origin xyz="0 0 0.01"/>
  </joint>
  <link name="imu_link">
    <visual>
      <origin rpy="0 0 0" xyz="0 0 0.0"/>
      <geometry>
        <box size="0.02 0.02 0.02"/>
      </geometry>
      <material name="orange"/>
    </visual>
    <inertial>
      <origin rpy="1.5707963267948966 0 1.5707963267948966" xyz="0 0 0"/>
      <mass value="0.01"/>
      <inertia ixx="6.666666666666667e-07" ixy="0.0" ixz="0.0" iyy="6.666666666666667e-07" iyz="0.0" izz="6.666666666666667e-07"/>
    </inertial>
  </link>
  <joint name="laser_ms200_joint" type="fixed">
    <parent link="base_link"/>
    <child link="laser_ms200_link"/>
    <origin xyz="-0.285 0.305 0.125"/>
  </joint>
  <link name="laser_ms200_link">
    <visual>
      <origin rpy="0 0 0" xyz="0 0 0"/>
      <geometry>
        <cylinder length="0.02" radius="0.02"/>
      </geometry>
      <material name="black"/>
    </visual>
    <inertial>
      <origin rpy="1.5707963267948966 0 0" xyz="0 0 0"/>
      <mass value="0.02"/>
      <inertia ixx="2.6666666666666664e-06" ixy="-4.2369783e-11" ixz="0" iyy="2.6666666666666664e-06" iyz="0" izz="4.000000000000001e-06"/>
    </inertial>
  </link>
  <joint name="livox_frame_joint" type="fixed">
    <parent link="base_link"/>
    <child link="livox_frame"/>
    <origin xyz="0.44 0.25 -0.08500000000000003"/>
  </joint>
  <link name="livox_frame">
    <visual>
      <origin rpy="0 0 0" xyz="0 0 0"/>
      <geometry>
        <cylinder length="0.02" radius="0.02"/>
      </geometry>
      <material name="black"/>
    </visual>
    <inertial>
      <origin rpy="1.5707963267948966 0 0" xyz="0 0 0"/>
      <mass value="0.02"/>
      <inertia ixx="2.6666666666666664e-06" ixy="-4.2369783e-11" ixz="0" iyy="2.6666666666666664e-06" iyz="0" izz="4.000000000000001e-06"/>
    </inertial>
  </link>
</robot>
