<sdf version='1.7'>
  <model name='wheelchair_base'>
    <link name='base_footprint'>
      <inertial>
        <pose>-0.133267 0.000125 0.44182 0 -0 0</pose>
        <mass>60.03</mass>
        <inertia>
          <ixx>1.97207</ixx>
          <ixy>-0.0009995</ixy>
          <ixz>-0.214559</ixz>
          <iyy>3.85536</iyy>
          <iyz>-0.00229885</iyz>
          <izz>2.78445</izz>
        </inertia>
      </inertial>
      <collision name='base_footprint_fixed_joint_lump__base_link_collision'>
        <pose>0 0 0.495 0 -0 0</pose>
        <geometry>
          <box>
            <size>1 0.435 0.3</size>
          </box>
        </geometry>
        <surface>
          <contact>
            <ode/>
          </contact>
          <friction>
            <ode/>
          </friction>
        </surface>
      </collision>
      <visual name='base_footprint_fixed_joint_lump__base_link_visual'>
        <pose>0 0.025 0.495 1.5708 0 -1.5708</pose>
        <geometry>
          <mesh>
            <scale>1 1 1</scale>
            <uri>model://nav2_sample/meshes/robot_base.STL</uri>
          </mesh>
        </geometry>
        <material>
          <script>
            <name>Gazebo/Red</name>
            <uri>file://media/materials/scripts/gazebo.material</uri>
          </script>
        </material>
      </visual>
      <visual name='base_footprint_fixed_joint_lump__rabbit_link_visual_1'>
        <pose>-0.2 0 0.415 1.5708 -0 1.5708</pose>
        <geometry>
          <mesh>
            <scale>3 3.6 3</scale>
            <uri>model://nav2_sample/meshes/rabbit.STL</uri>
          </mesh>
        </geometry>
      </visual>
      <visual name='base_footprint_fixed_joint_lump__laser_link_visual_2'>
        <pose>0 0.25 0.745 0 -0 0</pose>
        <geometry>
          <cylinder>
            <length>0.02</length>
            <radius>0.02</radius>
          </cylinder>
        </geometry>
        <material>
          <script>
            <name>Gazebo/Black</name>
            <uri>file://media/materials/scripts/gazebo.material</uri>
          </script>
        </material>
      </visual>
      <visual name='base_footprint_fixed_joint_lump__imu_link_visual_3'>
        <pose>0 0.25 0.755 0 -0 0</pose>
        <geometry>
          <box>
            <size>0.02 0.02 0.02</size>
          </box>
        </geometry>
      </visual>
      <sensor name='wc_lidar' type='ray'>
        <always_on>1</always_on>
        <visualize>1</visualize>
        <update_rate>5</update_rate>
        <ray>
          <scan>
            <horizontal>
              <samples>360</samples>
              <resolution>1</resolution>
              <min_angle>0</min_angle>
              <max_angle>6.28</max_angle>
            </horizontal>
          </scan>
          <range>
            <min>0.12</min>
            <max>20</max>
            <resolution>0.015</resolution>
          </range>
          <noise>
            <type>gaussian</type>
            <mean>0</mean>
            <stddev>0.01</stddev>
          </noise>
        </ray>
        <plugin name='scan' filename='libgazebo_ros_ray_sensor.so'>
          <ros>
            <remapping>~/out:=scan</remapping>
          </ros>
          <output_type>sensor_msgs/LaserScan</output_type>
          <frame_name>laser_link</frame_name>
        </plugin>
        <pose>0 0.25 0.745 0 -0 0</pose>
      </sensor>
      <gravity>1</gravity>
      <sensor name='wc_imu' type='imu'>
        <always_on>1</always_on>
        <update_rate>100</update_rate>
        <visualize>1</visualize>
        <imu>
          <angular_velocity>
            <x>
              <noise type='gaussian'>
                <mean>0</mean>
                <stddev>0.0002</stddev>
              </noise>
            </x>
            <y>
              <noise type='gaussian'>
                <mean>0</mean>
                <stddev>0.0002</stddev>
              </noise>
            </y>
            <z>
              <noise type='gaussian'>
                <mean>0</mean>
                <stddev>0.0002</stddev>
              </noise>
            </z>
          </angular_velocity>
          <linear_acceleration>
            <x>
              <noise type='gaussian'>
                <mean>0</mean>
                <stddev>0.017</stddev>
              </noise>
            </x>
            <y>
              <noise type='gaussian'>
                <mean>0</mean>
                <stddev>0.017</stddev>
              </noise>
            </y>
            <z>
              <noise type='gaussian'>
                <mean>0</mean>
                <stddev>0.017</stddev>
              </noise>
            </z>
          </linear_acceleration>
          <orientation>
            <x>
              <noise type='gaussian'>
                <mean>0.0</mean>
                <stddev>2e-3</stddev>
              </noise>
            </x>
            <y>
              <noise type='gaussian'>
                <mean>0.0</mean>
                <stddev>2e-3</stddev>
              </noise>
            </y>
            <z>
              <noise type='gaussian'>
                <mean>0.0</mean>
                <stddev>2e-3</stddev>
              </noise>
            </z>
          </orientation>
        </imu>
        <plugin name='wc_robot_imu' filename='libgazebo_ros_imu_sensor.so'>
          <initial_orientation_as_reference>0</initial_orientation_as_reference>
          <frame_name>imu_link</frame_name>
          <ros>
            <namespace>/imu</namespace>
            <remapping>~/out:=data</remapping>
          </ros>
        </plugin>
        <pose>0 0.25 0.755 0 -0 0</pose>
      </sensor>
    </link>
    <joint name='left_small_wheel_joint' type='revolute'>
      <pose relative_to='base_footprint'>0.175 0.2155 0.08 0 -0 0</pose>
      <parent>base_footprint</parent>
      <child>left_small_wheel_link</child>
      <axis>
        <xyz>0 1 0</xyz>
        <limit>
          <lower>-3.1415</lower>
          <upper>3.1415</upper>
          <effort>30</effort>
          <velocity>5</velocity>
        </limit>
        <dynamics>
          <spring_reference>0</spring_reference>
          <spring_stiffness>0</spring_stiffness>
        </dynamics>
      </axis>
    </joint>
    <link name='left_small_wheel_link'>
      <pose relative_to='left_small_wheel_joint'>0 0 0 0 -0 0</pose>
      <inertial>
        <pose>0 0 0 1.5708 -0 0</pose>
        <mass>1.5</mass>
        <inertia>
          <ixx>0.0026</ixx>
          <ixy>-4.23698e-11</ixy>
          <ixz>0</ixz>
          <iyy>0.0026</iyy>
          <iyz>0</iyz>
          <izz>0.0048</izz>
        </inertia>
      </inertial>
      <collision name='left_small_wheel_link_collision'>
        <pose>0 0 0 1.5708 -0 0</pose>
        <geometry>
          <cylinder>
            <length>0.04</length>
            <radius>0.08</radius>
          </cylinder>
        </geometry>
        <surface>
          <contact>
            <ode/>
          </contact>
          <friction>
            <ode>
              <mu>0.001</mu>
              <mu2>0.001</mu2>
            </ode>
          </friction>
        </surface>
      </collision>
      <visual name='left_small_wheel_link_visual'>
        <pose>0 0 0 0 -0 1.5708</pose>
        <geometry>
          <mesh>
            <scale>0.839895 0.839895 0.839895</scale>
            <uri>model://nav2_sample/meshes/small_wheel.STL</uri>
          </mesh>
        </geometry>
        <material>
          <script>
            <name>Gazebo/Black</name>
            <uri>file://media/materials/scripts/gazebo.material</uri>
          </script>
        </material>
      </visual>
    </link>
    <joint name='left_wheel_joint' type='revolute'>
      <pose relative_to='base_footprint'>-0.325 0.2675 0.27 0 -0 0</pose>
      <parent>base_footprint</parent>
      <child>left_wheel_link</child>
      <axis>
        <xyz>0 1 0</xyz>
        <limit>
          <lower>-1e+16</lower>
          <upper>1e+16</upper>
        </limit>
        <dynamics>
          <spring_reference>0</spring_reference>
          <spring_stiffness>0</spring_stiffness>
        </dynamics>
      </axis>
    </joint>
    <link name='left_wheel_link'>
      <pose relative_to='left_wheel_joint'>0 0 0 0 -0 0</pose>
      <inertial>
        <pose>0 0 0 1.5708 -0 0</pose>
        <mass>5.5</mass>
        <inertia>
          <ixx>0.103171</ixx>
          <ixy>-4.23698e-11</ixy>
          <ixz>0</ixz>
          <iyy>0.103171</iyy>
          <iyz>0</iyz>
          <izz>0.200475</izz>
        </inertia>
      </inertial>
      <collision name='left_wheel_link_collision'>
        <pose>0 0 0 1.5708 -0 0</pose>
        <geometry>
          <cylinder>
            <length>0.08</length>
            <radius>0.27</radius>
          </cylinder>
        </geometry>
        <surface>
          <contact>
            <ode/>
          </contact>
          <friction>
            <ode>
              <mu>2</mu>
              <mu2>2</mu2>
            </ode>
          </friction>
        </surface>
      </collision>
      <visual name='left_wheel_link_visual'>
        <pose>0 0 0 0 -0 1.5708</pose>
        <geometry>
          <mesh>
            <scale>0.981818 0.981818 0.981818</scale>
            <uri>model://nav2_sample/meshes/wheel2.STL</uri>
          </mesh>
        </geometry>
        <material>
          <script>
            <name>Gazebo/Black</name>
            <uri>file://media/materials/scripts/gazebo.material</uri>
          </script>
        </material>
      </visual>
    </link>
    <joint name='right_small_wheel_joint' type='revolute'>
      <pose relative_to='base_footprint'>0.175 -0.2155 0.08 0 -0 0</pose>
      <parent>base_footprint</parent>
      <child>right_small_wheel_link</child>
      <axis>
        <xyz>0 1 0</xyz>
        <limit>
          <lower>-3.1415</lower>
          <upper>3.1415</upper>
          <effort>30</effort>
          <velocity>5</velocity>
        </limit>
        <dynamics>
          <spring_reference>0</spring_reference>
          <spring_stiffness>0</spring_stiffness>
        </dynamics>
      </axis>
    </joint>
    <link name='right_small_wheel_link'>
      <pose relative_to='right_small_wheel_joint'>0 0 0 0 -0 0</pose>
      <inertial>
        <pose>0 0 0 1.5708 -0 0</pose>
        <mass>1.5</mass>
        <inertia>
          <ixx>0.0026</ixx>
          <ixy>-4.23698e-11</ixy>
          <ixz>0</ixz>
          <iyy>0.0026</iyy>
          <iyz>0</iyz>
          <izz>0.0048</izz>
        </inertia>
      </inertial>
      <collision name='right_small_wheel_link_collision'>
        <pose>0 0 0 1.5708 -0 0</pose>
        <geometry>
          <cylinder>
            <length>0.04</length>
            <radius>0.08</radius>
          </cylinder>
        </geometry>
        <surface>
          <contact>
            <ode/>
          </contact>
          <friction>
            <ode>
              <mu>0.001</mu>
              <mu2>0.001</mu2>
            </ode>
          </friction>
        </surface>
      </collision>
      <visual name='right_small_wheel_link_visual'>
        <pose>0 0 0 0 0 -1.5708</pose>
        <geometry>
          <mesh>
            <scale>0.839895 0.839895 0.839895</scale>
            <uri>model://nav2_sample/meshes/small_wheel.STL</uri>
          </mesh>
        </geometry>
        <material>
          <script>
            <name>Gazebo/Black</name>
            <uri>file://media/materials/scripts/gazebo.material</uri>
          </script>
        </material>
      </visual>
    </link>
    <joint name='right_wheel_joint' type='revolute'>
      <pose relative_to='base_footprint'>-0.325 -0.2675 0.27 0 -0 0</pose>
      <parent>base_footprint</parent>
      <child>right_wheel_link</child>
      <axis>
        <xyz>0 1 0</xyz>
        <limit>
          <lower>-1e+16</lower>
          <upper>1e+16</upper>
        </limit>
        <dynamics>
          <spring_reference>0</spring_reference>
          <spring_stiffness>0</spring_stiffness>
        </dynamics>
      </axis>
    </joint>
    <link name='right_wheel_link'>
      <pose relative_to='right_wheel_joint'>0 0 0 0 -0 0</pose>
      <inertial>
        <pose>0 0 0 1.5708 -0 0</pose>
        <mass>5.5</mass>
        <inertia>
          <ixx>0.103171</ixx>
          <ixy>-4.23698e-11</ixy>
          <ixz>0</ixz>
          <iyy>0.103171</iyy>
          <iyz>0</iyz>
          <izz>0.200475</izz>
        </inertia>
      </inertial>
      <collision name='right_wheel_link_collision'>
        <pose>0 0 0 1.5708 -0 0</pose>
        <geometry>
          <cylinder>
            <length>0.08</length>
            <radius>0.27</radius>
          </cylinder>
        </geometry>
        <surface>
          <contact>
            <ode/>
          </contact>
          <friction>
            <ode>
              <mu>2</mu>
              <mu2>2</mu2>
            </ode>
          </friction>
        </surface>
      </collision>
      <visual name='right_wheel_link_visual'>
        <pose>0 0 0 0 0 -1.5708</pose>
        <geometry>
          <mesh>
            <scale>0.981818 0.981818 0.981818</scale>
            <uri>model://nav2_sample/meshes/wheel2.STL</uri>
          </mesh>
        </geometry>
        <material>
          <script>
            <name>Gazebo/Black</name>
            <uri>file://media/materials/scripts/gazebo.material</uri>
          </script>
        </material>
      </visual>
    </link>
    <static>0</static>
    <plugin name='wc_robot_diff_drive' filename='libgazebo_ros_diff_drive.so'>
      <update_rate>30</update_rate>
      <left_joint>left_wheel_joint</left_joint>
      <right_joint>right_wheel_joint</right_joint>
      <wheel_separation>0.435</wheel_separation>
      <wheel_diameter>0.54</wheel_diameter>
      <max_wheel_torque>30</max_wheel_torque>
      <max_wheel_acceleration>0.2</max_wheel_acceleration>
      <command_topic>cmd_vel</command_topic>
      <publish_odom>1</publish_odom>
      <publish_odom_tf>1</publish_odom_tf>
      <publish_wheel_tf>1</publish_wheel_tf>
      <odometry_topic>odom</odometry_topic>
      <odometry_frame>odom</odometry_frame>
      <robot_base_frame>base_footprint</robot_base_frame>
    </plugin>
    <plugin name='wc_joint_state' filename='libgazebo_ros_joint_state_publisher.so'>
      <ros>
        <remapping>~/out:=joint_states</remapping>
      </ros>
      <update_rate>30</update_rate>
      <joint_name>left_small_wheel_joint</joint_name>
      <joint_name>right_small_wheel_joint</joint_name>
    </plugin>
  </model>
</sdf>
