<?xml version="1.0"?>
<robot name="gk01" xmlns:xacro="http://ros.org/wiki/xacro">
  
  <!-- ****************** ROBOT CONSTANTS *******************************  -->
  <!-- Define the size of the robot's main chassis in meters -->
  <xacro:property name="base_width" value="0.45" />
  <xacro:property name="base_length" value="0.6" />
  <xacro:property name="base_height" value="0.4" />
  <xacro:property name="base_link_high" value="0.1" />

  <!-- Define the shape of the robot's two back wheels in meters -->
  <xacro:property name="wheel_radius" value="0.170" />
  <xacro:property name="wheel_width" value="0.07" />
  <xacro:property name="wheel_ygap" value="0.6" />
  <xacro:property name="wheel_xoff" value="0.3" />
  <!-- <xacro:property name="wheel_joint_type" value="continuous" /> -->

  <xacro:property name="s_wheel_radius" value="0.1" />
  <xacro:property name="s_wheel_width" value="0.04" />
  <xacro:property name="s_wheel_ygap" value="0.5" />
  <xacro:property name="s_wheel_xoff" value="${wheel_xoff - 0.6}" /> 
  
  <!-- base_link to livox_frame -->
  <!-- 仅仅是为了兼容 -->
  <xacro:arg name="xyz" default="0.12 0.0 0.175" />
  <xacro:arg name="rpy" default="0 0 0" />

  <!-- Define intertial property macros  -->
  <xacro:macro name="box_inertia" params="m w h d or_z:=0">
    <inertial>
      <origin xyz="0 0 ${or_z}" rpy="${pi/2} 0 ${pi/2}" />
      <mass value="${m}" />
      <inertia ixx="${(m/12) * (h*h + d*d)}" ixy="0.0" ixz="0.0" iyy="${(m/12) * (w*w + d*d)}"
        iyz="0.0" izz="${(m/12) * (w*w + h*h)}" />
    </inertial>
  </xacro:macro>

  <xacro:macro name="cylinder_inertia" params="m r h">
    <inertial>
      <origin xyz="0 0 0" rpy="${pi/2} 0 0" />
      <mass value="${m}" />
      <inertia ixx="${(m/12) * (3*r*r + h*h)}" ixy="-4.2369783e-11" ixz="0" iyy="${(m/12) * (3*r*r + h*h)}"
        iyz="0" izz="${(m/2) * (r*r)}" />
    </inertial>
  </xacro:macro>

  <xacro:macro name="sphere_inertia" params="m r">
    <inertial>
      <mass value="${m}" />
      <inertia ixx="${(2/5) * m * (r*r)}" ixy="0.0" ixz="0.0" iyy="${(2/5) * m * (r*r)}" iyz="0.0"
        izz="${(2/5) * m * (r*r)}" />
    </inertial>
  </xacro:macro>

  <xacro:macro name="entity_material" params="color alpha">
    <material name="black">
      <color rgba="0.0 0.0 0.0 1.0" />
    </material>
  </xacro:macro>
  
  <xacro:property name="wheel_scale" value="${wheel_radius/0.1525}" />
  <xacro:property name="s_wheel_scale" value="${s_wheel_radius/0.0975}" />

  <!-- *********************** DRIVE WHEELS ******************************  -->

  <xacro:macro name="wheel" params="prefix x_reflect y_reflect">
    <link name="${prefix}_link">
      <visual>
          <origin xyz="0 0 0" rpy="${- y_reflect * pi/2} 0  0" />
          <geometry>
            <mesh filename="package://swc_nav_bringup/meshes/wheel3.STL"
              scale="${wheel_scale} ${wheel_scale} ${wheel_scale}" />
          </geometry>
          <material name="light_black" />
      </visual>
      <collision>
        <origin xyz="0 0 0" rpy="${pi/2} 0 0" />
        <geometry>
          <cylinder radius="${wheel_radius}" length="${wheel_width}" />
        </geometry>
      </collision>
      <xacro:cylinder_inertia m="5.5" r="${wheel_radius}" h="${wheel_width}" />
    </link>
    <joint name="${prefix}_joint" type="continuous">
      <parent link="base_link" />
      <child link="${prefix}_link" />
      <origin xyz="${x_reflect*wheel_xoff} ${y_reflect*(wheel_ygap/2)} ${-base_link_high + wheel_radius}"  rpy="0 0 0" />
      <axis xyz="0 1 0" />
      <!-- <limit upper="3.1415" lower="-3.1415" effort="30" velocity="5.0"/> -->
    </joint>
    <gazebo reference="${prefix}_link">
      <material>Gazebo/Black</material>
      <mu1>1.0</mu1>  <!-- 摩擦系数 -->
      <mu2>1.0</mu2>
    </gazebo>
  </xacro:macro>

  <xacro:macro name="small_wheel" params="prefix x_reflect y_reflect">
    <link name="${prefix}_link">
      <visual>
        <origin xyz="0 0 0" rpy="${y_reflect * pi/2} 0 0 " />
        <geometry>
          <mesh filename="package://swc_nav_bringup/meshes/small_wheel2.STL" scale="${s_wheel_scale} ${s_wheel_scale} ${s_wheel_scale}" />
        </geometry>
        <material name="light_black" />
      </visual>
      <collision>
        <origin xyz="0 0 0" rpy="${pi/2} 0 0" />
        <geometry>
          <cylinder radius="${s_wheel_radius}" length="${s_wheel_width}" />
        </geometry>
      </collision>
      <xacro:cylinder_inertia m="1.5" r="${s_wheel_radius}" h="${s_wheel_width}" />
    </link>

    <joint name="${prefix}_joint" type="continuous">
      <parent link="base_link" />
      <child link="${prefix}_link" />
      <origin xyz="${x_reflect*s_wheel_xoff} ${y_reflect*(s_wheel_ygap/2)} ${-base_link_high + s_wheel_radius}"
        rpy="0 0 0" />
      <axis xyz="0 1 0" />
      <limit upper="3.1415" lower="-3.1415" effort="30" velocity="5.0"/>
    </joint>
    <gazebo reference="${prefix}_link">
      <material>Gazebo/Black</material>
      <mu1>0.00001</mu1>  <!-- 摩擦系数 -->
      <mu2>0.00001</mu2>
    </gazebo>
  </xacro:macro>

  <!-- Init colour -->
  <material name="black">
    <color rgba="0.0 0.0 0.0 1.0" />
  </material>

  <material name="dark">
    <color rgba="0.3 0.3 0.3 1.0" />
  </material>

  <material name="light_black">
    <color rgba="0.7 0.7 0.7 1.0" />
  </material>

  <material name="blue">
    <color rgba="0.0 0.0 0.8 1.0" />
  </material>

  <material name="light_blue">
    <color rgba="${0/255} ${0/255} ${255/255} 0.5" />
  </material>

  <material name="green">
    <color rgba="0.0 0.8 0.0 1.0" />
  </material>

  <material name="grey">
    <color rgba="0.5 0.5 0.5 1.0" />
  </material>

  <material name="orange">
    <color rgba="1.0 0.4235 0.0392 1.0" />
  </material>

  <material name="brown">
    <color rgba="0.8706 0.8118 0.7647 1.0" />
  </material>

  <material name="red">
    <color rgba="0.8 0.0 0.0 1.0" />
  </material>

  <material name="white">
    <color rgba="1.0 1.0 1.0 1.0" />
  </material>
  
  <!-- ************************************************************************************************************************** -->
  <!-- ************************************************************************************************************************** -->
  <!-- ************************************************************************************************************************** -->
  <!-- ************************************************************************************************************************** -->

  <link name="base_footprint" />
  
  <joint name="base_joint" type="fixed">
    <parent link="base_footprint" />
    <child link="base_link" />
    <origin xyz="${wheel_xoff} 0 ${base_link_high}" rpy="0 0 0" />
  </joint>

  <!-- base link -->
  <link name="base_link">
    <visual>
      <origin xyz="0 0 ${base_height/2}" rpy="0 0 0" />
      <geometry>
        <!-- <mesh filename="package://swc_nav_bringup/meshes/robot_base.STL" scale="1.0 1.0 1.0"/> -->
        <box size="${base_length} ${base_width}   ${base_height}"/>
      </geometry>
      <material name="light_blue" />
    </visual>
    <collision>
      <origin xyz="0 0 ${base_height/2}" rpy="0 0 0" />
      <geometry>
        <box size="${base_length} ${base_width} ${base_height}"/>
      </geometry>
    </collision>
    <xacro:box_inertia m="20.0" w="${base_width}" d="${base_length}" h="${base_height}" or_z="${base_height/2}"/>
  </link>
  
  <xacro:wheel prefix="left_wheel" x_reflect="-1" y_reflect="1" />
  <xacro:wheel prefix="right_wheel" x_reflect="-1" y_reflect="-1" />

  <xacro:small_wheel prefix="left_small_wheel" x_reflect="-1" y_reflect="1" />
  <xacro:small_wheel prefix="right_small_wheel" x_reflect="-1" y_reflect="-1"/>

  <!-- laser joint -->
  <joint name="laser_joint" type="fixed">
    <parent link="base_link" />
    <child link="laser_link" />
    <origin xyz="${0.61-wheel_xoff} ${-s_wheel_ygap/2} ${-base_link_high+0.335}" />
  </joint>

  <!-- laser link -->
  <link name="laser_link">
    <visual>
      <origin xyz="0 0 0" rpy="0 0 0" />
      <geometry>
        <cylinder length="0.02" radius="0.02" />
      </geometry>
      <material name="black" />
    </visual>
    <xacro:cylinder_inertia m="0.02" r="0.02" h="0.02"/>
  </link>

  <!-- imu joint -->
  <joint name="imu_joint" type="fixed">
    <parent link="laser_link" />
    <child link="imu_link" />
    <origin xyz="0 0 0.01" />
  </joint>

  <link name="imu_link">
    <visual>
      <origin xyz="0 0 0.0" rpy="0 0 0" />
      <geometry>
        <box size="0.02 0.02 0.02" />
      </geometry>
      <material name="orange" />
    </visual>
    <xacro:box_inertia m="0.01" w="0.02" d="0.02" h="0.02"/>
  </link>

  <joint name="laser_ms200_joint" type="fixed">
    <parent link="base_link" />
    <child link="laser_ms200_link" />
    <origin xyz="${-wheel_xoff-0.1} 0 ${-base_link_high + 0.2}" />
  </joint>

  <link name="laser_ms200_link">
      <visual>
        <origin xyz="0 0 0" rpy="0 0 0" />
        <geometry>
          <cylinder length="0.02" radius="0.02" />
        </geometry>
        <material name="black" />
      </visual>
      <xacro:cylinder_inertia m="0.02" r="0.02" h="0.02"/>
  </link>

  <joint name="livox_frame_joint" type="fixed">
    <parent link="base_link" />
    <child link="livox_frame" />
    <origin xyz="${0.63-wheel_xoff} ${s_wheel_ygap/2} ${-base_link_high+ 0.345}" />
  </joint>

  <link name="livox_frame">
      <visual>
        <origin xyz="0 0 0" rpy="0 0 0" />
        <geometry>
          <cylinder length="0.02" radius="0.02" />
        </geometry>
        <material name="black" />
      </visual>
      <xacro:cylinder_inertia m="0.02" r="0.02" h="0.02"/>
  </link>

</robot>